Workbook

Sheet Raw Data
A1: LLOYDS BANKING GROUP PLC – SOURCE DATA (£ MILLIONS)
A4: CONSOLIDATED INCOME STATEMENT
A5: Line Item | B5: 2023 | C5: 2024 | D5: 2025
A6: Interest Income | B6: 28051 | C6: 31288 | D6: 30749
A7: Interest Expense | B7: -14753 | C7: -19011 | D7: -17519
A8: Net Interest Income | B8: 13298 | C8: 12277 | D8: 13230
A9: Fee & Commission Income | B9: 2926 | C9: 2943 | D9: 3118
A10: Fee & Commission Expense | B10: -1095 | C10: -1184 | D10: -1334
A11: Net Fee & Commission Income | B11: 1831 | C11: 1759 | D11: 1784
A12: Net Trading Income | B12: 1307 | C12: 1812 | D12: 1485
A13: Insurance Service Result | B13: 596 | C13: 486 | D13: 756
A14: Net Investment & Finance Result | B14: -34 | C14: -265 | D14: -200
A15: Other Operating Income | B15: 1631 | C15: 1934 | D15: 2367
A16: Other Income | B16: 5331 | C16: 5726 | D16: 6192
A17: Total Income | B17: 18629 | C17: 18003 | D17: 19422
... A23: Profit Attributable to Ord. Shareholders | B23: 4933 | C23: 3923 | D23: 4196
A26: CONSOLIDATED BALANCE SHEET
A27: Line Item | B27: 2023 | C27: 2024 | D27: 2025
A28: Cash & Central Bank Balances | C28: 62705 | D28: 56661
A29: Financial Assets at FVTPL | C29: 215925 | D29: 240413
A30: Derivative Financial Assets | C30: 24065 | D30: 19727
A31: Loans & Advances to Banks | C31: 7900 | D31: 7236
A32: Loans & Advances to Customers | B32: 459857 | C32: 459857 | D32: 481463
A33: Reverse Repurchase Agreements | C33: 49476 | D33: 50986
A34: Debt Securities (Amortised Cost) | C34: 14544 | D34: 13987
A35: Financial Assets at Amortised Cost | C35: 531777 | D35: 553672
A36: Financial Assets at FVOCI | C36: 30690 | D36: 36320
A37: Goodwill & Intangibles | C37: 8188 | D37: 8593
A38: Deferred Tax Assets | C38: 5005 | D38: 3990
A39: Other Assets | C39: 24788 | D39: 20655
A40: Total Assets | B40: 889931 | C40: 906697 | D40: 944072
A42: Customer Deposits | B42: 490000 | C42: 482745 | D42: 496457
A43: Deposits from Banks | C43: 6158 | D43: 5779
A44: Repurchase Agreements | C44: 37760 | D44: 38570
A45: Debt Securities in Issue | C45: 70834 | D45: 78271
A46: Subordinated Liabilities | C46: 10089 | D46: 9894
A47: Insurance & Investment Contract Liabs | C47: 122064 | D47: 135284
A48: Non-participating Investment Contracts | C48: 51228 | D48: 61640
A49: Provisions | C49: 2313 | D49: 2888
A50: Other Liabilities | C50: 60374 | D50: 67652
...

Sheet Profitability Ratios
A1: PROFITABILITY RATIOS – LLOYDS BANKING GROUP PLC (2023–2025)
A4: Ratio | B4: Formula Used | C4: 2023 | D4: 2024 | E4: 2025
A5: 1. Return on Equity (RoE) | B5: =pat / average ordinary shareholders' equity | C5: ='Raw Data'!B22/(('Raw Data'!B53+'Raw Data'!B53)/2) -> 0.116499525 | D5: ='Raw Data'!C22/(('Raw Data'!C53+'Raw Data'!B53)/2) -> 0.1030545773 | E5: ='Raw Data'!D22/(('Raw Data'!D53+'Raw Data'!C53)/2) -> 0.1171069151
A6: 2. Return on Assets (RoA) | B6: =pat / average total assets | C6: ='Raw Data'!B22/(('Raw Data'!B40+'Raw Data'!B40)/2) -> 0.006200480711 | D6: ='Raw Data'!C22/(('Raw Data'!C40+'Raw Data'!B40)/2) -> 0.004983780727 | E6: ='Raw Data'!D22/(('Raw Data'!D40+'Raw Data'!C40)/2) -> 0.005140565895
A7: 3. Return on Tangible Equity (RoTE) - Reported | B7: =as disclosed in annual report (p.308 apm) | C7: ='Raw Data'!B99 -> 0.158 | D7: ='Raw Data'!C99 -> 0.123 | E7: ='Raw Data'!D99 -> 0.129
A8: 4. Net Profit Margin | B8: =pat / total income | C8: ='Raw Data'!B22/'Raw Data'!B17 -> 0.2962048419 | D8: ='Raw Data'!C22/'Raw Data'!C17 -> 0.2486807754 | E8: ='Raw Data'!D22/'Raw Data'!D17 -> 0.2449284317
A9: 5. Pre-Tax Profit Margin | B9: =pbt / total income | C9: ='Raw Data'!B20/'Raw Data'!B17 -> 0.402759139 | D9: ='Raw Data'!C20/'Raw Data'!C17 -> 0.3316669444 | E9: ='Raw Data'!D20/'Raw Data'!D17 -> 0.3429615899
A10: 6. Banking Net Interest Margin (NIM) - Reported | B10: =nii / average interest-earning banking assets (apm) | C10: ='Raw Data'!B98 -> 0.0322 | D10: ='Raw Data'!C98 -> 0.0295 | E10: ='Raw Data'!D98 -> 0.0306
A11: 7. NIM Cross-Check (Statutory NII / Loans) | B11: =net interest income / average loans to customers | C11: ='Raw Data'!B8/(('Raw Data'!B32+'Raw Data'!B32)/2) -> 0.02891768528 | D11: ='Raw Data'!C8/(('Raw Data'!C32+'Raw Data'!B32)/2) -> 0.02669742985 | E11: ='Raw Data'!D8/(('Raw Data'!D32+'Raw Data'!C32)/2) -> 0.02810946331
A12: 8. Cost:Income Ratio (Underlying) - Reported | B12: =total underlying costs / underlying net income (apm, p.308) | C12: ='Raw Data'!B100 -> 0.581 | D12: ='Raw Data'!C100 -> 0.604 | E12: ='Raw Data'!D100 -> 0.586
A13: 9. Cost:Income Ratio (Statutory) | B13: =operating expenses / total income (statutory basis) | C13: =-'Raw Data'!B18/'Raw Data'!B17 -> 0.5809758978 | D13: =-'Raw Data'!C18/'Raw Data'!C17 -> 0.6443926012 | E13: =-'Raw Data'!D18/'Raw Data'!D17 -> 0.6161054474
A14: 10. Effective Tax Rate | B14: =tax expense / profit before tax | C14: =-'Raw Data'!B21/'Raw Data'!B20 -> 0.2645608423 | D14: =-'Raw Data'!C21/'Raw Data'!C20 -> 0.2502093452 | E14: =-'Raw Data'!D21/'Raw Data'!D20 -> 0.2858429665
A15: 11. Asset Quality Ratio (AQR) - Reported | B15: =impairment charge / average loans (apm) | C15: ='Raw Data'!B101 -> 0.0007 | D15: ='Raw Data'!C101 -> 0.001 | E15: ='Raw Data'!D101 -> 0.0017
A16: 12. AQR Cross-Check (Statutory) | B16: =impairment charge / average loans to customers | C16: =-'Raw Data'!B19/(('Raw Data'!B32+'Raw Data'!B32)/2) -> 0.0006589004843 | D16: =-'Raw Data'!C19/(('Raw Data'!C32+'Raw Data'!B32)/2) -> 0.0009372478836 | E16: =-'Raw Data'!D19/(('Raw Data'!D32+'Raw Data'!C32)/2) -> 0.00168911741

Sheet Liquidity Ratios
A1: LIQUIDITY RATIOS – LLOYDS BANKING GROUP PLC (2023–2025)
A4: Ratio | B4: Formula Used | C4: 2023 | D4: 2024 | E4: 2025 | F4: Benchmark
A5: 1. Loan-to-Deposit Ratio (LDR) | B5: =loans & advances to customers / customer deposits | C5: ='Raw Data'!B32/'Raw Data'!B42 -> 0.9384836735 | D5: ='Raw Data'!C32/'Raw Data'!C42 -> 0.9525878052 | E5: ='Raw Data'!D32/'Raw Data'!D42 -> 0.9697979885 | F5: <100% (PRA preference)
A6: 2. Liquidity Coverage Ratio (LCR) - Reported | B6: =hqla / 30-day net cash outflows under stress (apm, p.188) | C6: ='Raw Data'!B106 -> 1.5 | D6: ='Raw Data'!C106 -> 1.46 | E6: ='Raw Data'!D106 -> 1.45 | F6: >100% (CRD IV minimum)
A7: 3. Net Stable Funding Ratio (NSFR) - Reported | B7: =available stable funding / required stable funding (apm, p.188) | C7: N/A | D7: ='Raw Data'!C107 -> 1.29 | E7: ='Raw Data'!D107 -> 1.24 | F7: >100% (CRD IV minimum)
A8: 4. Cash & Central Bank Balances (£m) | B8: =cash held at central banks and in hand (balance sheet) | C8: N/A | D8: ='Raw Data'!C28 -> 62705 | E8: ='Raw Data'!D28 -> 56661 | F8: LBG internal risk appetite
A9: 5. Current Ratio Proxy (Liquid Assets / Deposits) | B9: =(cash + fvtpl assets) / customer deposits | C9: N/A | D9: =('Raw Data'!C28+'Raw Data'!C29)/'Raw Data'!C42 -> 0.5771784275 | E9: =('Raw Data'!D28+'Raw Data'!D29)/'Raw Data'!D42 -> 0.5983881786 | F9: >50% (internal target)
A10: 6. Wholesale Funding / Total Liabilities | B10: =debt securities in issue / total liabilities | C10: N/A | D10: ='Raw Data'!C45/'Raw Data'!C51 -> 0.08228770842 | E10: ='Raw Data'!D45/'Raw Data'!D51 -> 0.08733604477 | F10: Minimise (< 15%)

Sheet Efficiency Ratios
A1: EFFICIENCY RATIOS – LLOYDS BANKING GROUP PLC (2023–2025)
A4: Ratio | B4: Formula Used | C4: 2023 | D4: 2024 | E4: 2025
A5: 1. Cost:Income (Underlying APM) - Reported | B5: =total underlying costs / underlying net income (apm) | C5: ='Raw Data'!B100 -> 0.581 | D5: ='Raw Data'!C100 -> 0.604 | E5: ='Raw Data'!D100 -> 0.586
A6: 2. Cost:Income (Statutory) | B6: =operating expenses / total income | C6: =-'Raw Data'!B18/'Raw Data'!B17 -> 0.5809758978 | D6: =-'Raw Data'!C18/'Raw Data'!C17 -> 0.6443926012 | E6: =-'Raw Data'!D18/'Raw Data'!D17 -> 0.6161054474
A7: 3. Operating Costs per £bn of Assets | B7: =operating expenses (£m) / Total Assets (£bn) → £m/£bn) | C7: =-'Raw Data'!B18/('Raw Data'!B40/1000) -> 12.16161702 | D7: =-'Raw Data'!C18/('Raw Data'!C40/1000) -> 12.79479253 | E7: =-'Raw Data'!D18/('Raw Data'!D40/1000) -> 12.67488073
A8: 4. Asset Quality Ratio (Impairment / Avg Loans) - Calc. | B8: =|impairment charge| / average loans & advances to customers | C8: =-'Raw Data'!B19/(('Raw Data'!B32+'Raw Data'!B32)/2) -> 0.0006589004843 | D8: =-'Raw Data'!C19/(('Raw Data'!C32+'Raw Data'!B32)/2) -> 0.0009372478836 | E8: =-'Raw Data'!D19/(('Raw Data'!D32+'Raw Data'!C32)/2) -> 0.00168911741
A9: 5. AQR - Reported APM | B9: =as disclosed in annual report (apm, p.308) | C9: ='Raw Data'!B101 -> 0.0007 | D9: ='Raw Data'!C101 -> 0.001 | E9: ='Raw Data'!D101 -> 0.0017
A10: 6. Income per Employee (proxy, £m per 1,000 staff) | B10: =total income / 56 (thousands of employees, approx.) | C10: ='Raw Data'!B17/56 -> 332.6607143 | D10: ='Raw Data'!C17/56 -> 321.4821429 | E10: ='Raw Data'!D17/56 -> 346.8214286
A11: 7. NII as % of Total Income | B11: =net interest income / total income | C11: ='Raw Data'!B8/'Raw Data'!B17 -> 0.7138332707 | D11: ='Raw Data'!C8/'Raw Data'!C17 -> 0.6819418986 | E11: ='Raw Data'!D8/'Raw Data'!D17 -> 0.6811862836
A12: 8. Other Income as % of Total Income | B12: =other income / total income (income diversification) | C12: ='Raw Data'!B16/'Raw Data'!B17 -> 0.2861667293 | D12: ='Raw Data'!C16/'Raw Data'!C17 -> 0.3180581014 | E12: ='Raw Data'!D16/'Raw Data'!D17 -> 0.3188137164

Sheet Solvency Ratios
A1: SOLVENCY RATIOS – LLOYDS BANKING GROUP PLC (2023–2025)
A4: Ratio | B4: Formula Used | C4: 2023 | D4: 2024 | E4: 2025 | F4: Regulatory Min.
A5: 1. CET1 Capital Ratio (Statutory) - Reported | B5: =CET1 capital / risk-weighted assets (basel iii) | C5: ='Raw Data'!B102 -> 0.137 | D5: ='Raw Data'!C102 -> 0.142 | E5: ='Raw Data'!D102 -> 0.14 | F5: ≥4.5% (Basel III) / ~12% (PRA SREP incl. buffers)
A6: 2. Pro-Forma CET1 Ratio - Reported | B6: =CET1 post declared buyback/dividend (apm, p.308) | C6: ='Raw Data'!B103 -> 0.137 | D6: ='Raw Data'!C103 -> 0.135 | E6: ='Raw Data'!D103 -> 0.132 | F6: LBG target: ~13.0% by end-2026
A7: 3. UK Leverage Ratio - Reported | B7: =tier 1 capital / total leverage exposure (uk crr) | C7: N/A | D7: ='Raw Data'!C104 -> 0.055 | E7: ='Raw Data'!D104 -> 0.054 | F7: ≥3.25% (PRA minimum)
A8: 4. Debt-to-Equity Ratio (Total Liabilities / Total Equity) | B8: =total liabilities / total equity | C8: ='Raw Data'!B51/'Raw Data'!B56 -> 17.78878919 | D8: ='Raw Data'!C51/'Raw Data'!C56 -> 18.75891301 | E8: ='Raw Data'!D51/'Raw Data'!D56 -> 18.7228153 | F8: High in banking (normal: 10-20x)
A9: 5. Equity Multiplier (Total Assets / Total Equity) | B9: =total assets / total equity (financial leverage) | C9: ='Raw Data'!B40/'Raw Data'!B56 -> 18.78878919 | D9: ='Raw Data'!C40/'Raw Data'!C56 -> 19.75891301 | E9: ='Raw Data'!D40/'Raw Data'!D56 -> 19.7228153 | F9: Normal for banks: 15-25x
A10: 6. Tangible Equity / Total Assets | B10: =(ordinary shareholders equity - goodwill) / total assets | C10: =('Raw Data'!B53-'Raw Data'!B37)/'Raw Data'!B40 -> 0.05322322742 | D10: =('Raw Data'!C53-'Raw Data'!C37)/'Raw Data'!C40 -> 0.03455729974 | E10: =('Raw Data'!D53-'Raw Data'!D37)/'Raw Data'!D40 -> 0.03509054394 | F10: LBG internal capital adequacy
A11: 7. Total Capital Adequacy (Equity / Assets) - Simple | B11: =total equity / total assets | C11: ='Raw Data'!B56/'Raw Data'!B40 -> 0.05322322742 | D11: ='Raw Data'!C56/'Raw Data'!C40 -> 0.0506100715 | E11: ='Raw Data'!D56/'Raw Data'!D40 -> 0.05070270064 | F11: Higher = more conservative

Sheet Investor Ratios
A1: INVESTOR RATIOS – LLOYDS BANKING GROUP PLC (2023–2025)
A4: Ratio | B4: Formula Used | C4: 2023 | D4: 2024 | E4: 2025
A5: 1. Basic Earnings Per Share (EPS) | B5: =profit attr. to ord. shareholders / wanos (note 31, p.287) | C5: ='Raw Data'!B23/'Raw Data'!B113 -> 0.07594722338 | D5: ='Raw Data'!C23/'Raw Data'!C113 -> 0.06285549485 | E5: ='Raw Data'!D23/'Raw Data'!D113 -> 0.07017895969
A6: 2. EPS (Reported, pence) - Cross-check | B6: =as disclosed in note 31 annual report | C6: ='Raw Data'!B95*100 -> 7.6 | D6: ='Raw Data'!C95*100 -> 6.3 | E6: ='Raw Data'!D95*100 -> 7
A7: 3. Dividends Per Share (DPS) - Ordinary | B7: =total declared ordinary dividend / shares (disclosed, p.19) | C7: ='Raw Data'!B96*100 -> 2.76 | D7: ='Raw Data'!C96*100 -> 3.17 | E7: ='Raw Data'!D96*100 -> 3.65
A8: 4. Dividend Payout Ratio | B8: =dps / eps (% of earnings paid as dividends) | C8: ='Raw Data'!B96/'Raw Data'!B95 -> 0.3631578947 | D8: ='Raw Data'!C96/'Raw Data'!C95 -> 0.5031746032 | E8: ='Raw Data'!D96/'Raw Data'!D95 -> 0.5214285714
A9: 5. DPS Growth Year-on-Year | B9: =(dps_t - dps_{t-1}) / dps_{t-1} | C9: N/A | D9: =('Raw Data'!C96-'Raw Data'!B96)/'Raw Data'!B96 -> 0.1485507246 | E9: =('Raw Data'!D96-'Raw Data'!C96)/'Raw Data'!C96 -> 0.1514195584
A10: 6. Tangible Net Assets Per Share (TNAV) - Reported | B10: =(ord. equity - intangibles) / shares in issue (apm, p.308) | C10: N/A | D10: ='Raw Data'!C97*100 -> 52.4 | E10: ='Raw Data'!D97*100 -> 57
A11: 7. TNAV Per Share Growth Year-on-Year | B11: =(tnav_t - tnav_{t-1}) / tnav_{t-1} | C11: N/A | D11: N/A | E11: =('Raw Data'!D97-'Raw Data'!C97)/'Raw Data'!C97 -> 0.08778625954
A12: 8. Total Shareholder Return (in-year) - Reported | B12: =(share price change + dividend) / opening share PRICE(p.19) | C12: ='Raw Data'!B112 -> 0.109 | D12: ='Raw Data'!C112 -> 0.212 | E12: ='Raw Data'!D112 -> 0.879
A13: 9. Capital Return Yield (Dividends + Buybacks as % of equity) | B13: =(ord. dividends + share buyback) / avg ord. shareholders equity | C13: =('Raw Data'!B76*-1+'Raw Data'!B83*-1)/(('Raw Data'!B53+'Raw Data'!B53)/2) -> 0.07693444527 | D13: =('Raw Data'!C76*-1+'Raw Data'!C83*-1)/(('Raw Data'!C53+'Raw Data'!B53)/2) -> 0.08836866699 | E13: =('Raw Data'!D76*-1+'Raw Data'!D83*-1)/(('Raw Data'!D53+'Raw Data'!C53)/2) -> 0.09133206962
A14: 10. Return on Tangible Equity (RoTE) vs Peer Average | B14: =lbg rote minus peer average rote (outperformance) | C14: ='Raw Data'!B99-'Raw Data'!B111 -> 0.039 | D14: ='Raw Data'!C99-'Raw Data'!C111 -> 0.007 | E14: ='Raw Data'!D99-'Raw Data'!D111 -> 0.011

Sheet Trend Analysis
A1: YEAR-ON-YEAR TREND ANALYSIS – LLOYDS BANKING GROUP PLC (2023–2025)
A4: Metric | B4: 2023 | C4: 2024 | D4: YoY 23→24 Δ | E4: 2025 | F4: YoY 24→25 Δ
A5: Total Income (£m) | B5: ='Raw Data'!B17 -> 18629 | C5: ='Raw Data'!C17 -> 18003 | D5: =(C5-B5)/ABS(B5) -> -0.03360352139 | E5: ='Raw Data'!D17 -> 19422 | F5: =(E5-C5)/ABS(C5) -> 0.07882019663
A6: Net Interest Income (£m) | B6: ='Raw Data'!B8 -> 13298 | C6: ='Raw Data'!C8 -> 12277 | D6: =(C6-B6)/ABS(B6) -> -0.07677846293 | E6: ='Raw Data'!D8 -> 13230 | F6: =(E6-C6)/ABS(C6) -> 0.07762482691
A7: Other Income (£m) | B7: ='Raw Data'!B16 -> 5331 | C7: ='Raw Data'!C16 -> 5726 | D7: =(C7-B7)/ABS(B7) -> 0.07409491653 | E7: ='Raw Data'!D16 -> 6192 | F7: =(E7-C7)/ABS(C7) -> 0.08138316451
A8: Operating Expenses (£m) | B8: ='Raw Data'!B18 -> -10823 | C8: ='Raw Data'!C18 -> -11601 | D8: =(C8-B8)/ABS(B8) -> -0.07188395085 | E8: ='Raw Data'!D18 -> -11966 | F8: =(E8-C8)/ABS(C8) -> -0.03146280493
A9: Impairment Charge (£m) | B9: ='Raw Data'!B19 -> -303 | C9: ='Raw Data'!C19 -> -431 | D9: =(C9-B9)/ABS(B9) -> -0.4224422442 | E9: ='Raw Data'!D19 -> -795 | F9: =(E9-C9)/ABS(C9) -> -0.8445475638
A10: Profit Before Tax (£m) | B10: ='Raw Data'!B20 -> 7503 | C10: ='Raw Data'!C20 -> 5971 | D10: =(C10-B10)/ABS(B10) -> -0.2041849927 | E10: ='Raw Data'!D20 -> 6661 | F10: =(E10-C10)/ABS(C10) -> 0.1155585329
A11: Profit After Tax (£m) | B11: ='Raw Data'!B22 -> 5518 | C11: ='Raw Data'!C22 -> 4477 | D11: =(C11-B11)/ABS(B11) -> -0.1886553099 | E11: ='Raw Data'!D22 -> 4757 | F11: =(E11-C11)/ABS(C11) -> 0.06254188072
A12: Return on Equity (RoE) | B12: ='Profitability Ratios'!C5 -> 0.116499525 | C12: ='Profitability Ratios'!D5 -> 0.1030545773 | D12: =(C12-B12)/ABS(B12) -> -0.115407747 | E12: ='Profitability Ratios'!E5 -> 0.1171069151 | F12: =(E12-C12)/ABS(C12) -> 0.1363582119
A13: Return on Tangible Equity (RoTE) | B13: ='Raw Data'!B99 -> 0.158 | C13: ='Raw Data'!C99 -> 0.123 | D13: =(C13-B13)/ABS(B13) -> -0.2215189873 | E13: ='Raw Data'!D99 -> 0.129 | F13: =(E13-C13)/ABS(C13) -> 0.0487804878
A14: Net Profit Margin | B14: ='Profitability Ratios'!C8 -> 0.2962048419 | C14: ='Profitability Ratios'!D8 -> 0.2486807754 | D14: =(C14-B14)/ABS(B14) -> -0.1604432466 | E14: ='Profitability Ratios'!E8 -> 0.2449284317 | F14: =(E14-C14)/ABS(C14) -> -0.01508899811
A15: Banking NIM | B15: ='Raw Data'!B98 -> 0.0322 | C15: ='Raw Data'!C98 -> 0.0295 | D15: =(C15-B15)/ABS(B15) -> -0.08385093168 | E15: ='Raw Data'!D98 -> 0.0306 | F15: =(E15-C15)/ABS(C15) -> 0.03728813559
A16: Cost:Income (Underlying) | B16: ='Raw Data'!B100 -> 0.581 | C16: ='Raw Data'!C100 -> 0.604 | D16: =(C16-B16)/ABS(B16) -> 0.0395869191 | E16: ='Raw Data'!D100 -> 0.586 | F16: =(E16-C16)/ABS(C16) -> -0.0298013245
A17: Asset Quality Ratio (AQR) | B17: ='Raw Data'!B101 -> 0.0007 | C17: ='Raw Data'!C101 -> 0.001 | D17: =(C17-B17)/ABS(B17) -> 0.4285714286 | E17: ='Raw Data'!D101 -> 0.0017 | F17: =(E17-C17)/ABS(C17) -> 0.7
A18: Loan-to-Deposit Ratio (LDR) | B18: ='Raw Data'!B105 -> 0.939 | C18: ='Raw Data'!C105 -> 0.953 | D18: =(C18-B18)/ABS(B18) -> 0.01490947817 | E18: ='Raw Data'!D105 -> 0.97 | F18: =(E18-C18)/ABS(C18) -> 0.01783840504
A19: LCR | B19: ='Raw Data'!B106 -> 1.5 | C19: ='Raw Data'!C106 -> 1.46 | D19: =(C19-B19)/ABS(B19) -> -0.02666666667 | E19: ='Raw Data'!D106 -> 1.45 | F19: =(E19-C19)/ABS(C19) -> -0.006849315068
A20: CET1 Ratio (Statutory) | B20: ='Raw Data'!B102 -> 0.137 | C20: ='Raw Data'!C102 -> 0.142 | D20: =(C20-B20)/ABS(B20) -> 0.03649635036 | E20: ='Raw Data'!D102 -> 0.14 | F20: =(E20-C20)/ABS(C20) -> -0.01408450704
A21: Basic EPS (pence) | B21: ='Raw Data'!B95*100 -> 7.6 | C21: ='Raw Data'!C95*100 -> 6.3 | D21: =(C21-B21)/ABS(B21) -> -0.1710526316 | E21: ='Raw Data'!D95*100 -> 7 | F21: =(E21-C21)/ABS(C21) -> 0.1111111111
A22: Dividends Per Share (pence) | B22: ='Raw Data'!B96*100 -> 2.76 | C22: ='Raw Data'!C96*100 -> 3.17 | D22: =(C22-B22)/ABS(B22) -> 0.1485507246 | E22: ='Raw Data'!D96*100 -> 3.65 | F22: =(E22-C22)/ABS(C22) -> 0.1514195584
A23: Total Assets (£m) | B23: ='Raw Data'!B40 -> 889931 | C23: ='Raw Data'!C40 -> 906697 | D23: =(C23-B23)/ABS(B23) -> 0.01883966285 | E23: ='Raw Data'!D40 -> 944072 | F23: =(E23-C23)/ABS(C23) -> 0.04122104738
A24: Loans & Advances to Customers (£m) | B24: ='Raw Data'!B32 -> 459857 | C24: ='Raw Data'!C32 -> 459857 | D24: =(C24-B24)/ABS(B24) -> 0 | E24: ='Raw Data'!D32 -> 481463 | F24: =(E24-C24)/ABS(C24) -> 0.04698417117
A25: Customer Deposits (£m) | B25: ='Raw Data'!B42 -> 490000 | C25: ='Raw Data'!C42 -> 482745 | D25: =(C25-B25)/ABS(B25) -> -0.01480612245 | E25: ='Raw Data'!D42 -> 496457 | F25: =(E25-C25)/ABS(C25) -> 0.02840422998

Sheet Benchmarking
A1: COMPETITOR & INDUSTRY BENCHMARKING – LBG vs UK BANKING PEERS (FY2025)
A4: Metric | B4: Formula / Source | C4: LBG 2025 | D4: Barclays ~2025 | E4: NatWest ~2025 | F4: HSBC ~2025 | G4: Peer Average | H4: LBG vs Avg
A5: Return on Tangible Equity (RoTE) | B5: LBG: Raw Data KPIs | Peers: published results / LBG AR2025 p.138 | C5: ='Raw Data'!D99 -> 0.129 | D5: 0.125 | E5: 0.14 | F5: 0.14 | G5: =AVERAGE(D5:F5) -> 0.135 | H5: =C5-G5 -> -0.006
A6: CET1 Capital Ratio | B6: LBG: Raw Data KPIs | Peers: company disclosures | C6: ='Raw Data'!D102 -> 0.14 | D6: 0.132 | E6: 0.139 | F6: 0.149 | G6: =AVERAGE(D6:F6) -> 0.14 | H6: =C6-G6 -> 0
A7: Cost:Income Ratio (Underlying / Adjusted) | B7: LBG: Raw Data KPIs | Peers: adjusted results | C7: ='Raw Data'!D100 -> 0.586 | D7: 0.61 | E7: 0.55 | F7: 0.47 | G7: =AVERAGE(D7:F7) -> 0.5433333333 | H7: =C7-G7 -> 0.04266666667
A8: Banking Net Interest Margin | B8: LBG: Raw Data KPIs | NatWest/Barclays: UK banking NIM; HSBC: global avg | C8: ='Raw Data'!D98 -> 0.0306 | D8: 0.028 | E8: 0.028 | F8: 0.015 | G8: =AVERAGE(D8:F8) -> 0.02366666667 | H8: =C8-G8 -> 0.006933333333
A9: Loan-to-Deposit Ratio | B9: LBG: Raw Data KPIs | Peers: company disclosures | C9: ='Raw Data'!D105 -> 0.97 | D9: 0.95 | E9: 0.88 | F9: 0.75 | G9: =AVERAGE(D9:F9) -> 0.86 | H9: =C9-G9 -> 0.11
A10: Dividend Per Share Growth (YoY %) | B10: LBG: Investor Ratios sheet | Peers: company announcements | C10: ='Investor Ratios'!E9 -> 0.1514195584 | D10: 0.1 | E10: 0.1 | F10: 0.15 | G10: =AVERAGE(D10:F10) -> 0.1166666667 | H10: =C10-G10 -> 0.03475289169
A11: Total Shareholder Return (FY2025, %) | B11: LBG: Raw Data KPIs | Peers: Bloomberg/market data | C11: ='Raw Data'!D112 -> 0.879 | D11: 0.35 | E11: 0.25 | F11: 0.15 | G11: =AVERAGE(D11:F11) -> 0.25 | H11: =C11-G11 -> 0.629
A12: Asset Quality Ratio (AQR / credit loss rate) | B12: LBG: Raw Data KPIs | Peers: impairment charge / avg loans | C12: ='Raw Data'!D101 -> 0.0017 | D12: 0.0035 | E12: 0.002 | F12: 0.0025 | G12: =AVERAGE(D12:F12) -> 0.002666666667 | H12: =C12-G12 -> -0.0009666666667

Sheet Capital Structure & WCM
A1: CAPITAL STRUCTURE & WORKING CAPITAL MANAGEMENT – LLOYDS BANKING GROUP PLC
A3: A. CAPITAL STRUCTURE ANALYSIS
A4: Metric | B4: Formula / Source | C4: 2023 | D4: 2024 | E4: 2025
A5: Ordinary Shareholders' Equity (£m) | B5: Balance Sheet | C5: ='Raw Data'!B53 -> 47365 | D5: ='Raw Data'!C53 -> 39521 | E5: ='Raw Data'!D53 -> 41721
A6: Other Equity Instruments / AT1 (£m) | B6: Balance Sheet | C6: ='Raw Data'!B54 -> 6940 | D6: ='Raw Data'!C54 -> 6195 | E6: ='Raw Data'!D54 -> 5947
A7: Subordinated Liabilities / Tier 2 (£m) | B7: Balance Sheet | C7: ='Raw Data'!B46 | D7: ='Raw Data'!C46 -> 10089 | E7: ='Raw Data'!D46 -> 9894
A8: Debt Securities in Issue (£m) | B8: Balance Sheet - wholesale funding | C8: ='Raw Data'!B45 | D8: ='Raw Data'!C45 -> 70834 | E8: ='Raw Data'!D45 -> 78271
A9: Customer Deposits (£m) | B9: Balance Sheet - retail funding | C9: ='Raw Data'!B42 -> 490000 | D9: ='Raw Data'!C42 -> 482745 | E9: ='Raw Data'!D42 -> 496457
A10: Total Equity (£m) | B10: Balance Sheet | C10: ='Raw Data'!B56 -> 47365 | D10: ='Raw Data'!C56 -> 45888 | E10: ='Raw Data'!D56 -> 47867
A11: Total Liabilities (£m) | B11: Balance Sheet | C11: ='Raw Data'!B51 -> 842566 | D11: ='Raw Data'!C51 -> 860809 | E11: ='Raw Data'!D51 -> 896205
A12: Debt-to-Equity Ratio | B12: =total liabilities / total equity | C12: ='Raw Data'!B51/'Raw Data'!B56 -> 17.78878919 | D12: ='Raw Data'!C51/'Raw Data'!C56 -> 18.75891301 | E12: ='Raw Data'!D51/'Raw Data'!D56 -> 18.7228153
A13: Equity Multiplier | B13: =total assets / total equity | C13: ='Raw Data'!B40/'Raw Data'!B56 -> 18.78878919 | D13: ='Raw Data'!C40/'Raw Data'!C56 -> 19.75891301 | E13: ='Raw Data'!D40/'Raw Data'!D56 -> 19.7228153
A14: Deposits as % of Total Funding | B14: =customer deposits / (total liabilities + total equity) | C14: ='Raw Data'!B42/('Raw Data'!B51+'Raw Data'!B56) -> 0.5506044851 | D14: ='Raw Data'!C42/('Raw Data'!C51+'Raw Data'!C56) -> 0.5324215256 | E14: ='Raw Data'!D42/('Raw Data'!D51+'Raw Data'!D56) -> 0.5258677304
A15: CET1 Ratio (Statutory) | B15: =CET1 capital / risk-weighted assets (pra) | C15: ='Raw Data'!B102 -> 0.137 | D15: ='Raw Data'!C102 -> 0.142 | E15: ='Raw Data'!D102 -> 0.14
A16: Ordinary Dividends Paid (£m) | B16: Cash Flow Statement | C16: ='Raw Data'!B76*-1 -> 1651 | D16: ='Raw Data'!C76*-1 -> 1828 | E16: ='Raw Data'!D76*-1 -> 2000
A17: Share Buyback (£m) | B17: Cash Flow Statement | C17: ='Raw Data'!B83*-1 -> 1993 | D17: ='Raw Data'!C83*-1 -> 2011 | E17: ='Raw Data'!D83*-1 -> 1710
A18: Total Capital Returns (Dividend + Buyback) (£m) | B18: =|dividends| + |buyback| | C18: ='Raw Data'!B76*-1+'Raw Data'!B83*-1 -> 3644 | D18: ='Raw Data'!C76*-1+'Raw Data'!C83*-1 -> 3839 | E18: ='Raw Data'!D76*-1+'Raw Data'!D83*-1 -> 3710
A19: Capital Return as % of PAT | B19: =total capital returns / profit after tax | C19: =(ABS('Raw Data'!B76)+ABS('Raw Data'!B83))/'Raw Data'!B22 -> 0.6603841972 | D19: =(ABS('Raw Data'!C76)+ABS('Raw Data'!C83))/'Raw Data'!C22 -> 0.8574938575 | E19: =(ABS('Raw Data'!D76)+ABS('Raw Data'!D83))/'Raw Data'!D22 -> 0.7799033004
A22: B. WORKING CAPITAL MANAGEMENT ANALYSIS
A23: Metric | B23: Formula / Source | C23: 2023 | D23: 2024 | E23: 2025
A24: Loan-to-Deposit Ratio (LDR) | B24: =loans & advances / customer deposits | C24: ='Raw Data'!B32/'Raw Data'!B42 -> 0.9384836735 | D24: ='Raw Data'!C32/'Raw Data'!C42 -> 0.9525878052 | E24: ='Raw Data'!D32/'Raw Data'!D42 -> 0.9697979885
A25: Liquidity Coverage Ratio (LCR) | B25: Reported APM (p.188) | C25: ='Raw Data'!B106 -> 1.5 | D25: ='Raw Data'!C106 -> 1.46 | E25: ='Raw Data'!D106 -> 1.45
A26: Net Stable Funding Ratio (NSFR) | B26: Reported APM (p.188) | C26: N/A | D26: ='Raw Data'!C107 -> 1.29 | E26: ='Raw Data'!D107 -> 1.24
A27: Closing Cash Balance (£m) | B27: Cash Flow Statement | C27: ='Raw Data'!B90 -> 88838 | D27: ='Raw Data'!C90 -> 70816 | E27: ='Raw Data'!D90 -> 60593
A28: Net Cash from Operations (£m) | B28: Cash Flow Statement | C28: ='Raw Data'!B68 -> 6810 | D28: ='Raw Data'!C68 -> -4393 | E28: ='Raw Data'!D68 -> 5701
A29: Net Cash from Investing (£m) | B29: Cash Flow Statement | C29: ='Raw Data'!B75 -> -9821 | D29: ='Raw Data'!C75 -> -7691 | E29: ='Raw Data'!D75 -> -10189
A30: Net Cash from Financing (£m) | B30: Cash Flow Statement | C30: ='Raw Data'!B86 -> -3500 | D30: ='Raw Data'!C86 -> -5931 | E30: ='Raw Data'!D86 -> -5357
A31: Net Change in Cash (£m) | B31: Cash Flow Statement | C31: ='Raw Data'!B88 -> -6991 | D31: ='Raw Data'!C88 -> -18022 | E31: ='Raw Data'!D88 -> -10223
A32: Customer Deposit Growth (YoY) | B32: =(deposits_t - deposits_{t-1}) / deposits_{t-1} | C32: N/A | D32: =('Raw Data'!C42-'Raw Data'!B42)/'Raw Data'!B42 -> -0.01480612245 | E32: =('Raw Data'!D42-'Raw Data'!C42)/'Raw Data'!C42 -> 0.02840422998
A33: Loan Portfolio Growth (YoY) | B33: =(loans_t - loans_{t-1}) / loans_{t-1} | C33: N/A | D33: =('Raw Data'!C32-'Raw Data'!B32)/'Raw Data'!B32 -> 0 | E33: =('Raw Data'!D32-'Raw Data'!C32)/'Raw Data'!C32 -> 0.04698417117
A34: Deposit-Loan Gap (£m, positive = deposit surplus) | B34: =customer deposits - loans to customers | C34: ='Raw Data'!B42-'Raw Data'!B32 -> 30143 | D34: ='Raw Data'!C42-'Raw Data'!C32 -> 22888 | E34: ='Raw Data'!D42-'Raw Data'!D32 -> 14994
A35: Interest Received (£m) | B35: Cash Flow Note (p.217) | C35: N/A | D35: =29721 -> 29721 | E35: =29843 -> 29843
A36: Interest Paid (£m) | B36: Cash Flow Note (p.217) | C36: N/A | D36: =17840 -> 17840 | E36: =16589 -> 16589
A37: Net Interest Spread (Received minus Paid, £m) | B37: =interest received - interest paid | C37: N/A | D37: =D35-D36 -> 11881 | E37: =E35-E36 -> 13254
